<?xml version="1.0"?>
<robot xmlns:sensor="http://playerstage.sourceforge.net/gazebo/xmlschema/#sensor"
	 xmlns:controller="http://playerstage.sourceforge.net/gazebo/xmlschema/#controller"
	 xmlns:interface="http://playerstage.sourceforge.net/gazebo/xmlschema/#interface"
	 xmlns:xacro="http://playerstage.sourceforge.net/gazebo/xmlschema/#interface"
	 name="lewis">

<xacro:property name="thickness" value=".013" />


<xacro:macro name="easy_cylinder" params="name radius length *origin *material">
<link name="${name}">
	<visual>
		<xacro:insert_block name="origin" />
		<geometry>
			<cylinder radius="${radius}" length="${length}" />
		</geometry>

		<xacro:insert_block name="material" />
	</visual>

	<collision>
		<xacro:insert_block name="origin" />
		<geometry>
			<cylinder radius="${radius}" length="${length}" />
		</geometry>
	</collision>
</link>
</xacro:macro>

<xacro:macro name="easy_box" params="name size *origin *material">
<link name="${name}">
	<visual>
		<xacro:insert_block name="origin" />
		<geometry>
			<box size="${size}" />
		</geometry>
		<xacro:insert_block name="material" />
	</visual>

	<collision>
		<xacro:insert_block name="origin" />
		<geometry>
			<box size="${size}" />
		</geometry>	
	</collision>
</link>
</xacro:macro>

<xacro:macro name="fixedjoint" params="name parent child *origin">
<joint name="${name}" type="fixed">
	<xacro:insert_block name="origin" />
	<parent link="${parent}"/>
	<child link="${child}"/>
</joint>
</xacro:macro>

<xacro:easy_cylinder name="base_link" radius="0.10" length=".30">
	<origin xyz="0 0 .15"/>
	<material name="black">
		<color rgba="0 0 0 1"/>
	</material>
</xacro:easy_cylinder>

<xacro:easy_cylinder name="body" radius="0.25" length=".53">
	<origin xyz="0 0 .265"/>
	<material name="lewisred">
		<color rgba="1 0 0 1"/>
	</material>
</xacro:easy_cylinder>

<xacro:fixedjoint name="base_to_body" parent="base_link" child="body">
	<origin xyz="0 0 .40"/>
</xacro:fixedjoint>

<xacro:easy_cylinder name="base" radius="0.26" length=".30">
	<origin xyz="0 0 .15"/>
	<material name="lewisred"/>
</xacro:easy_cylinder>

<joint name="lewis_twist" type="continuous">
	<parent link="body"/>
	<child link="base"/>
	<origin xyz="0 0 -.40"/>
	<axis xyz="0 0 1"/>
</joint>

<xacro:easy_box name="connector" size=".15 .30 .1">
	<origin />
	<material name="black"/>
</xacro:easy_box>

<xacro:fixedjoint name="connect" parent="body" child="connector">
	<origin xyz="-0.12 0 -.05"/>
</xacro:fixedjoint>

<xacro:easy_box name="laserbase" size=".04 .04 .04">
	<origin />
	<material name="gray">
		<color rgba=".8 .8 .8 1"/>
	</material>
</xacro:easy_box>

<xacro:fixedjoint name="tolaserbase" parent="body" child="laserbase">
	<origin xyz="-0.29 0 -.08"/>
</xacro:fixedjoint>

<xacro:easy_cylinder name="laser" radius="0.02" length=".03">
	<origin/>
	<material name="black" />
</xacro:easy_cylinder>

<xacro:fixedjoint name="tolaser" parent="laserbase" child="laser">
	<origin xyz="0 0 .035"/>
</xacro:fixedjoint>

<xacro:easy_cylinder name="bodytop" radius="0.25" length=".02">
	<origin/>
	<material name="black" />
</xacro:easy_cylinder>

<xacro:fixedjoint name="totop" parent="body" child="bodytop">
	<origin xyz="0 0 .54"/>
</xacro:fixedjoint>

<xacro:macro name="brace" params="prefix sign">
	<xacro:easy_box name="${prefix}brace" size="0.1 .01 .13">
		<origin />
		<material name="black" />
	</xacro:easy_box>
	<xacro:fixedjoint name="to${prefix}brace" parent="bodytop" child="${prefix}brace">
		<origin xyz="0 ${sign}0.20 .075"/>
	</xacro:fixedjoint>
</xacro:macro>

<xacro:brace prefix="left" sign="" />
<xacro:brace prefix="right" sign="-" />

<xacro:easy_box name="platform" size="0.30 .50 .06" >
	<origin />
	<material name="lewisred"/>
</xacro:easy_box>
<xacro:fixedjoint name="toplatform" parent="bodytop" child="platform">
	<origin xyz="0.1 0 .17"/>
</xacro:fixedjoint>

<xacro:easy_box name="graybase" size="0.14 .25 .005" >
	<origin />
	<material name="gray"/>
</xacro:easy_box>

<xacro:fixedjoint name="tograybase" parent="platform" child="graybase">
	<origin xyz="0.02 0 .0325"/>
</xacro:fixedjoint>

<xacro:macro name="post" params="num xsign ysign">
	<xacro:easy_cylinder name="post${num}" length=".155" radius="0.005">
		<origin />
		<material name="gray"/>
	</xacro:easy_cylinder>
	<xacro:fixedjoint name="topost${num}" parent="graybase" child="post${num}">
		<origin xyz="${xsign}0.03 ${ysign}0.115 .08" />
	</xacro:fixedjoint>
</xacro:macro>

<xacro:post num="1" xsign="" ysign="" />
<xacro:post num="2" xsign="" ysign="-" />
<xacro:post num="3" xsign="-" ysign="" />
<xacro:post num="4" xsign="-" ysign="-" />

<xacro:easy_box name="graytop" size="0.135 .25 .005">
	<origin/>
	<material name="gray"/>
</xacro:easy_box>
<xacro:fixedjoint name="tograytop" parent="graybase" child="graytop">
	<origin xyz="0.02 0 .155"/>
</xacro:fixedjoint>

<xacro:easy_box name="ptu_base" size="0.04 .07 .05">	
	<origin xyz="0 0.015 0"/>
	<material name="black"/>
</xacro:easy_box>
<xacro:fixedjoint name="toptubase" parent="graytop" child="ptu_base">
	<origin xyz="0 -0.0075 .0275"/>
</xacro:fixedjoint>

<xacro:easy_box name="ptu_piece" size="0.04 .04 .06">	
	<origin/>
	<material name="black"/>
</xacro:easy_box>

<joint name="pan" type="continuous">
	<origin xyz="0 0 .055"/>
	<axis xyz="0 0 1"/>
	<parent link="ptu_base"/>
	<child link="ptu_piece"/>
</joint>

<xacro:easy_box name="ptu_mount" size="0.04 .27 .03">	
	<origin/>
	<material name="gray"/>
</xacro:easy_box>

<joint name="tilt" type="continuous">
	<origin xyz="0 0 .065"/>
	<axis xyz="0 -1 0"/>
	<parent link="ptu_piece"/>
	<child link="ptu_mount"/>
</joint>

<xacro:macro name="eye" params="prefix sign">
<link name="${prefix}eye">
	<visual>
		<geometry>
			<sphere radius="0.04"/>
		</geometry>
		<material name="black"/>
	</visual>
	<collision>
		<geometry>
			<sphere radius="0.04" />
		</geometry>
	</collision>
</link>
<xacro:fixedjoint name="to${prefix}eye" parent="ptu_mount" child="${prefix}eye">
	<origin xyz="0.05 ${sign}0.11 .02"/>
</xacro:fixedjoint>
</xacro:macro>

<xacro:eye prefix="left" sign="" />
<xacro:eye prefix="right" sign="-" />

<xacro:macro name="sonar" params="name parent xyz yaw">
<link name="${name}">
	<visual>
	    <origin rpy="0 1.51 0"/>
		<geometry>
			<cylinder radius=".02" length=".01" />
		</geometry>
		<material name="black"/>
	</visual>
</link>
<xacro:fixedjoint name="to${name}" parent="${parent}" child="${name}">
    <origin xyz="${xyz}" rpy="0 0 ${yaw}"/>
</xacro:fixedjoint>    
</xacro:macro>

<xacro:sonar name="base_sonar_0" parent="base" xyz="0.000000 0.260000 .06" yaw="1.570796" />
<xacro:sonar name="base_sonar_1" parent="base" xyz="0.067293 0.251141 .06" yaw="1.308997" />
<xacro:sonar name="base_sonar_2" parent="base" xyz="0.130000 0.225167 .06" yaw="1.047198" />
<xacro:sonar name="base_sonar_3" parent="base" xyz="0.183848 0.183848 .06" yaw="0.785398" />
<xacro:sonar name="base_sonar_4" parent="base" xyz="0.225167 0.130000 .06" yaw="0.523599" />
<xacro:sonar name="base_sonar_5" parent="base" xyz="0.251141 0.067293 .06" yaw="0.261799" />
<xacro:sonar name="base_sonar_6" parent="base" xyz="0.260000 0.000000 .06" yaw="0.000000" />
<xacro:sonar name="base_sonar_7" parent="base" xyz="0.251141 -0.067293 .06" yaw="-0.261799" />
<xacro:sonar name="base_sonar_8" parent="base" xyz="0.225167 -0.130000 .06" yaw="-0.523599" />
<xacro:sonar name="base_sonar_9" parent="base" xyz="0.183848 -0.183848 .06" yaw="-0.785398" />
<xacro:sonar name="base_sonar_10" parent="base" xyz="0.130000 -0.225167 .06" yaw="-1.047198" />
<xacro:sonar name="base_sonar_11" parent="base" xyz="0.067293 -0.251141 .06" yaw="-1.308997" />
<xacro:sonar name="base_sonar_12" parent="base" xyz="0.000000 -0.260000 .06" yaw="-1.570796" />
<xacro:sonar name="base_sonar_13" parent="base" xyz="-0.067293 -0.251141 .06" yaw="-1.832596" />
<xacro:sonar name="base_sonar_14" parent="base" xyz="-0.130000 -0.225167 .06" yaw="-2.094395" />
<xacro:sonar name="base_sonar_15" parent="base" xyz="-0.183848 -0.183848 .06" yaw="-2.356194" />
<xacro:sonar name="base_sonar_16" parent="base" xyz="-0.225167 -0.130000 .06" yaw="-2.617994" />
<xacro:sonar name="base_sonar_17" parent="base" xyz="-0.251141 -0.067293 .06" yaw="-2.879793" />
<xacro:sonar name="base_sonar_18" parent="base" xyz="-0.260000 -0.000000 .06" yaw="-3.141593" />
<xacro:sonar name="base_sonar_19" parent="base" xyz="-0.251141 0.067293 .06" yaw="-3.403392" />
<xacro:sonar name="base_sonar_20" parent="base" xyz="-0.225167 0.130000 .06" yaw="-3.665191" />
<xacro:sonar name="base_sonar_21" parent="base" xyz="-0.183848 0.183848 .06" yaw="-3.926991" />
<xacro:sonar name="base_sonar_22" parent="base" xyz="-0.130000 0.225167 .06" yaw="-4.188790" />
<xacro:sonar name="base_sonar_23" parent="base" xyz="-0.067293 0.251141 .06" yaw="-4.450590" />
<xacro:sonar name="body_sonar_0" parent="body" xyz="-0.250000 0.000000 .35"  yaw="3.141593" />
<xacro:sonar name="body_sonar_1" parent="body" xyz="-0.241481 0.064705 .35"  yaw="2.879793" />
<xacro:sonar name="body_sonar_2" parent="body" xyz="-0.216506 0.125000 .35"  yaw="2.617994" />
<xacro:sonar name="body_sonar_3" parent="body" xyz="-0.176777 0.176777 .35"  yaw="2.356194" />
<xacro:sonar name="body_sonar_4" parent="body" xyz="-0.125000 0.216506 .35"  yaw="2.094395" />
<xacro:sonar name="body_sonar_5" parent="body" xyz="-0.064705 0.241481 .35"  yaw="1.832596" />
<xacro:sonar name="body_sonar_6" parent="body" xyz="0.000000 0.250000 .35"  yaw="1.570796" />
<xacro:sonar name="body_sonar_7" parent="body" xyz="0.064705 0.241481 .35"  yaw="1.308997" />
<xacro:sonar name="body_sonar_8" parent="body" xyz="0.125000 0.216506 .35"  yaw="1.047198" />
<xacro:sonar name="body_sonar_9" parent="body" xyz="0.176777 0.176777 .35"  yaw="0.785398" />
<xacro:sonar name="body_sonar_10" parent="body" xyz="0.216506 0.125000 .35"  yaw="0.523599" />
<xacro:sonar name="body_sonar_11" parent="body" xyz="0.241481 0.064705 .35"  yaw="0.261799" />
<xacro:sonar name="body_sonar_12" parent="body" xyz="0.250000 0.000000 .35"  yaw="0.000000" />
<xacro:sonar name="body_sonar_13" parent="body" xyz="0.241481 -0.064705 .35"  yaw="-0.261799" />
<xacro:sonar name="body_sonar_14" parent="body" xyz="0.216506 -0.125000 .35"  yaw="-0.523599" />
<xacro:sonar name="body_sonar_15" parent="body" xyz="0.176777 -0.176777 .35"  yaw="-0.785398" />
<xacro:sonar name="body_sonar_16" parent="body" xyz="0.125000 -0.216506 .35"  yaw="-1.047198" />
<xacro:sonar name="body_sonar_17" parent="body" xyz="0.064705 -0.241481 .35"  yaw="-1.308997" />
<xacro:sonar name="body_sonar_18" parent="body" xyz="0.000000 -0.250000 .35"  yaw="-1.570796" />
<xacro:sonar name="body_sonar_19" parent="body" xyz="-0.064705 -0.241481 .35"  yaw="-1.832596" />
<xacro:sonar name="body_sonar_20" parent="body" xyz="-0.125000 -0.216506 .35"  yaw="-2.094395" />
<xacro:sonar name="body_sonar_21" parent="body" xyz="-0.176777 -0.176777 .35"  yaw="-2.356194" />
<xacro:sonar name="body_sonar_22" parent="body" xyz="-0.216506 -0.125000 .35"  yaw="-2.617994" />
<xacro:sonar name="body_sonar_23" parent="body" xyz="-0.241481 -0.064705 .35"  yaw="-2.879793" />


</robot>

